Workbook
Name iva: '[1]Ejercicio1 '!$J$1
Name TIPO_DE_CURSO: '[2]validacion dependiente 1'!$F$3:$F$4

Sheet Instrucciones
D1: ESCRIBE TU NOMBRE
C3: REALIZA LOS EJERCICIOS DE CADA HOJA.
C4: En cada hoja viene el enunciado del mismo
C5: Al final crea un menú en la hoja menú para poder enlazar con los ejercicios. (y pon formato "bonito")
B8: Nota alumno | C8: Puntuación de los ejercicios
B9: =+Ejercicio1!B1 -> 0 | C9: Ejercicio1 | D9: 1 | E9: Crear el menú y dar formato al documento
B10: =+'Ejercicio 2'!B1 -> 0 | C10: Ejercicio2 | D10: 1.5
B11: =+'Ejercicio 3A'!B1+'Ejercicio 3B'!B1+'Ejercicio 3C'!B1 -> 0 | C11: Ejercicio3 | D11: 1 | E11: Cada filtro 0,33
B12: =+'Ejercicio 4'!B1 -> 0 | C12: Ejercicio4 | D12: 2
B13: =+'Ejercicio 5'!B1 -> 0 | C13: Ejercicio5 | D13: 4.5
B17: =SUM(B9:B16) -> 0 | D17: =SUM(D9:D16) -> 10

Sheet Menu

Sheet 15 de noviembre
A1: NOTA
C2: Enunciado :
A3: NOMBRE | B3: PRODUCTO | C3: ZONA DE VENTA | D3: UNIDADES | E3: PRECIO UNIDAD | F3: TOTAL DE LA VENTA | G3: FECHA DE LA VENTA | I3: Esta tabla muestra los datos de ventas de 2022 y 2024, DE VARIOS PRODUCTOS Y VARIOS VENDEDORES. Se quiere dejar de vender en una de las zonas y de uno de los trabajadores. Crea un informe, que ayude a tomar la decisión con los datos proporcinados. EXPLICA TU RESPUESTA.
A4: TRSITAN | B4: TV | C4: NORTE | D4: 6 | G4: 44829
A5: ADRIAN | B5: ORDENADOR | C5: SUR | D5: 24 | G5: 45351
A6: LIZ | B6: IMPRESORA | C6: NORTE | D6: 5 | G6: 44746
A7: CRISTINA | B7: TV | C7: ESTE | D7: 24 | G7: 45437 | K7: TV | L7: 399
A8: TRSITAN | B8: ORDENADOR | C8: NORTE | D8: 3 | G8: 44811 | K8: ORDENADOR | L8: 799
A9: ADRIAN | B9: IMPRESORA | C9: SUR | D9: 7 | G9: 45522 | K9: IMPRESORA | L9: 169
A10: LIZ | B10: TV | C10: NORTE | D10: 11 | G10: 45265
A11: CRISTINA | B11: ORDENADOR | C11: SUR | D11: 21 | G11: 44873 | J11: 1 | K11: Para poner el precio unidad usa la fórmula SI usando la tabla de arriba
A12: TRSITAN | B12: IMPRESORA | C12: NORTE | D12: 3 | G12: 45274 | J12: 2 | K12: El total de venta es precio unidad por las unidades
A13: ADRIAN | B13: TV | C13: SUR | D13: 13 | G13: 45523
A14: LIZ | B14: ORDENADOR | C14: NORTE | D14: 10 | G14: 44591
A15: CRISTINA | B15: IMPRESORA | C15: ESTE | D15: 22 | G15: 45460 | K15: FORMATO CONDICIONAL.
A16: TRSITAN | B16: TV | C16: NORTE | D16: 19 | G16: 44591 | K16: Si las ventas son de tv de la zona norte el nombre del vendedor aparece en azil
A17: ADRIAN | B17: ORDENADOR | C17: SUR | D17: 19 | G17: 44850 | K17: Si el tota de ventas es mayor a 3000 toda la línea es roja
A18: LIZ | B18: IMPRESORA | C18: NORTE | D18: 25 | G18: 45226
A19: CRISTINA | B19: TV | C19: SUR | D19: 11 | G19: 45465
A20: TRSITAN | B20: ORDENADOR | C20: NORTE | D20: 15 | G20: 45542
A21: ADRIAN | B21: IMPRESORA | C21: SUR | D21: 14 | G21: 44749 | K21: *cuida la presentación
A22: LIZ | B22: TV | C22: NORTE | D22: 14 | G22: 44876
A23: CRISTINA | B23: ORDENADOR | C23: SUR | D23: 19 | G23: 45212
A24: TRSITAN | B24: IMPRESORA | C24: NORTE | D24: 15 | G24: 44979
A25: ADRIAN | B25: TV | C25: SUR | D25: 15 | G25: 45176
A26: LIZ | B26: ORDENADOR | C26: NORTE | D26: 19 | G26: 45315
A27: CRISTINA | B27: IMPRESORA | C27: SUR | D27: 25 | G27: 45140
A28: TRSITAN | B28: TV | C28: NORTE | D28: 8 | G28: 44695
A29: ADRIAN | B29: ORDENADOR | C29: SUR | D29: 12 | G29: 44680
A30: LIZ | B30: IMPRESORA | C30: NORTE | D30: 17 | G30: 45405
A31: CRISTINA | B31: TV | C31: SUR | D31: 3 | G31: 45364
A32: TRSITAN | B32: ORDENADOR | C32: NORTE | D32: 10 | G32: 45346
A33: ADRIAN | B33: IMPRESORA | C33: SUR | D33: 20 | G33: 45452
... A47: CRISTINA | B47: TV | C47: SUR | D47: 20 | G47: 44906
A48: TRSITAN | B48: ORDENADOR | C48: NORTE | D48: 19 | G48: 45179 | N48: La mayor venta la hizo eva y la menor la hizo juan
A49: ADRIAN | B49: IMPRESORA | C49: ESTE | D49: 14 | G49: 44786
A50: LIZ | B50: TV | C50: NORTE | D50: 8 | G50: 45298
A51: CRISTINA | B51: ORDENADOR | C51: SUR | D51: 6 | G51: 45265
A52: TRSITAN | B52: IMPRESORA | C52: NORTE | D52: 13 | G52: 45087
A53: ADRIAN | B53: TV | C53: SUR | D53: 11 | G53: 45456
...

Sheet Ejercicio1
A1: NOTA | B1: =+I16 -> 0
B2: Enunciado: | C2: Realiza los siguientes formatos condicionales | G2: Cada pregunta vale 0,25
C4: VENDEDOR | D4: COCHE | E4: POBLACIÓN | F4: VENTAS | G4: ZONA
C5: Sara | D5: SI | E5: MADRID | F5: 6728 | G5: NORTE | J5: 0.25 | K5: 1) Las celdas donde ponga Madrid y de la zona SUR, en la columna de problación que aparezcan el texto en rojo
C6: Marcos | D6: SI | E6: MADRID | F6: 8505 | G6: SUR
C7: Daniel | D7: NO | E7: MARDID | F7: 2992 | G7: ESTE
C8: Alejandro | D8: NO | E8: MADRID | F8: 9239 | G8: NORTE | J8: 0.25 | K8: 2) El nombre de los vendedores que su nombre empiece con M el color de texto azul.
C9: Marcos | D9: NO | E9: BARCELONA | F9: 6902 | G9: SUR
C10: Luis Miguel | D10: SI | E10: BARCELONA | F10: 5541 | G10: ESTE
C11: Roberto | D11: SI | E11: BARCELONA | F11: 3289 | G11: NORTE | J11: 0.25 | K11: 3) La fila donde la zona sea norte, con color de fondo vede.
C12: Nicolas | D12: SI | E12: BARCELONA | F12: 5825 | G12: SUR
C13: Cesar | D13: SI | E13: MADRID | F13: 8826 | G13: ESTE
C14: María | D14: SI | E14: BARECLONA | F14: 6463 | G14: NORTE | J14: 0.25 | K14: 4) Comprueba que los datos de población son correctos, utilizando alguna herramienta de Excel, sabiendo que solo se puede escribir MADRID O BARCELONA
C15: Mario | D15: NO | E15: MADRID | F15: 7506 | G15: SUR
C16: Alejandro | D16: NO | E16: MADRID | F16: 2077 | G16: ESTE | I16: =SUM(I5,I8,I11,I14) -> 0

Sheet Ejercicio 2
A1: NOTA | B1: =+J8 -> 0 | C1: 0,25 CADA UNA
B2: Enunciado: | C2: Separa utilizando funciones de excel el nombre de los apellidos y del teléfono (Puedes usar columnas adicionales). Si el telefono es fijo, el nombre se pondrá en azul
C4: tamaño | D4: valor de la , | E4: Nombre | F4: Apellidos | G4: Teléfono | I4: 1 | K4: nombre | L4: 0.25
B5: LOPEZ, GONZALEZ, SARA ALEJANDRA,666666661 | C5: =LEN(B5) -> 41 | D5: =FIND(",",B5) -> 6 | E5: =RIGHT(B5,C5-D15+11-D5+13) -> LOPEZ, GONZALEZ, SARA ALEJANDRA,666666661 | G5: =RIGHT(B5,C5-D15-10-D5-8) -> 666666661 | I5: 2 | K5: Apellidos | L5: 0.5
B6: AHMED, MONNE, MARCOS,666666662 | C6: =LEN(B6) -> 30 | D6: =FIND(",",B6) -> 6 | E6: =RIGHT(B6,C6-D16+11-D6+13) -> AHMED, MONNE, MARCOS,666666662 | G6: =RIGHT(B6,C6-D16-1-D6-7) -> 666666662 | I6: 3 | K6: Teléfono | L6: 0.25
B7: GARCIA, SERRANO, MARCOS,666666663 | C7: =LEN(B7) -> 33 | D7: =FIND(",",B7) -> 7 | E7: =RIGHT(B7,C7-D17+11-D7+13) -> GARCIA, SERRANO, MARCOS,666666663 | G7: =RIGHT(B7,C7-D17-1-D7-8) -> 666666663 | I7: 4 | K7: formato condicional | L7: 0.5
B8: GARCIA, LAPEÑA, DANIEL,666666664 | C8: =LEN(B8) -> 32 | D8: =FIND(",",B8) -> 7 | E8: =RIGHT(B8,C8-D18+11-D8+13) -> GARCIA, LAPEÑA, DANIEL,666666664 | G8: =RIGHT(B8,C8-D18-1-D8-8) -> 666666664 | J8: =SUM(J4:J7) -> 0
B9: CONDE, MORALES, ALEJANDRO,666666665 | C9: =LEN(B9) -> 35 | D9: =FIND(",",B9) -> 6 | E9: =RIGHT(B9,C9-D19+11-D9+13) -> CONDE, MORALES, ALEJANDRO,666666665 | G9: =RIGHT(B9,C9-D19-12-D9-8) -> 666666665
B10: LABRADA, ORTEGA, LUIS MIGUEL,666666666 | C10: =LEN(B10) -> 38 | D10: =FIND(",",B10) -> 8 | E10: =RIGHT(B10,C10-D20+11-D10+13) -> LABRADA, ORTEGA, LUIS MIGUEL,666666666 | G10: =RIGHT(B10,C10-D20-12-D10-2) -> 666666666
B11: BELTRE, CARMONA, LUIS ANGEL,666666667 | C11: =LEN(B11) -> 37 | D11: =FIND(",",B11) -> 7 | E11: =RIGHT(B11,C11-D21+11-D11+13) -> BELTRE, CARMONA, LUIS ANGEL,666666667 | G11: =RIGHT(B11,C11-D21-12-D11-9) -> 666666667
B12: MUÑOZ, ZORRO, ROBERTO,666666668 | C12: =LEN(B12) -> 31 | D12: =FIND(",",B12) -> 6 | E12: =RIGHT(B12,C12-D22+11-D12+13) -> MUÑOZ, ZORRO, ROBERTO,666666668 | G12: =RIGHT(B12,C12-D22-10-D12-6) -> 666666668
B13: TEXEIRA, BARBA, JOSE ANTONIO,666666669 | C13: =LEN(B13) -> 38 | D13: =FIND(",",B13) -> 8 | E13: =RIGHT(B13,C13-D23+11-D13+13) -> TEXEIRA, BARBA, JOSE ANTONIO,666666669 | G13: =RIGHT(B13,C13-D23-10-D13-11) -> 666666669
B14: CARDENAS, RODRIGUEZ, NICOLAS,666666670 | C14: =LEN(B14) -> 38 | D14: =FIND(",",B14) -> 9 | E14: =RIGHT(B14,C14-D24+11-D14+13) -> CARDENAS, RODRIGUEZ, NICOLAS,666666670 | G14: =RIGHT(B14,C14-D24-10-D14-10) -> 666666670
B15: SOBRINO, ARRIBAS, CESAR,666666671 | C15: =LEN(B15) -> 33 | D15: =FIND(",",B15) -> 8 | E15: =RIGHT(B15,C15-D25+11-D15+13) -> SOBRINO, ARRIBAS, CESAR,666666671 | G15: =RIGHT(B15,C15-D25-10-D15-6) -> 666666671
B16: TORRES, MARTINEZ, MARIA,666666672 | C16: =LEN(B16) -> 33 | D16: =FIND(",",B16) -> 7 | E16: =RIGHT(B16,C16-D26+11-D16+13) -> TORRES, MARTINEZ, MARIA,666666672 | G16: =RIGHT(B16,C16-D26-10-D16-7) -> 666666672
B17: NAVARRO, VALLEJO, MARIO,666666673 | C17: =LEN(B17) -> 33 | D17: =FIND(",",B17) -> 8 | E17: =RIGHT(B17,C17-D27+11-D17+13) -> NAVARRO, VALLEJO, MARIO,666666673 | G17: =RIGHT(B17,C17-D27-10-D17-6) -> 666666673
B18: OCHOVO, QUERO, ALEJANDRO,666666674 | C18: =LEN(B18) -> 34 | D18: =FIND(",",B18) -> 7 | E18: =RIGHT(B18,C18-D28+11-D18+13) -> OCHOVO, QUERO, ALEJANDRO,666666674 | G18: =RIGHT(B18,C18-D28-10-D18-8) -> 666666674
B20: naiara, lezameta | C20: =LEN(B20) -> 16 | D20: =FIND(",",B20) -> 7

Sheet Ejercicio 3A
A1: NOTA | B1: =+I4 -> 0
B2: Enunciado: | C2: Realiza los filtros indicados (cada filtro puntua 0,33)
K3: Filtra los productos en los que su nombre contenga la letra O , en total este entre 1000 y 4000 Euros o sean de Juan y de TV
A4: NOMBRE | B4: PRODUCTO | C4: ZONA DE VENTA | D4: UNIDADES | E4: PRECIO | F4: TOTAL | G4: FECHA DE LA VENTA | J4: Enunciado:
A5: JUAN | B5: TV | C5: NORTE | D5: 10 | E5: 399 | F5: =D5*E5 -> 3990 | G5: 43664
A6: MARIA | B6: ORDENADOR | C6: SUR | D6: 12 | E6: 299 | F6: =D6*E6 -> 3588 | G6: 43528
A7: EVA | B7: IMPRESORA | C7: NORTE | D7: 14 | E7: 99 | F7: =D7*E7 -> 1386 | G7: 43668
A8: PEDRO | B8: TV | C8: SUR | D8: 16 | E8: 399 | F8: =D8*E8 -> 6384 | G8: 43706
A9: JUAN | B9: ORDENADOR | C9: NORTE | D9: 18 | E9: 299 | F9: =D9*E9 -> 5382 | G9: 43594
A10: MARIA | B10: IMPRESORA | C10: SUR | D10: 20 | E10: 99 | F10: =D10*E10 -> 1980 | G10: 43746
A11: EVA | B11: TV | C11: NORTE | D11: 22 | E11: 399 | F11: =D11*E11 -> 8778 | G11: 43693
A12: PEDRO | B12: ORDENADOR | C12: SUR | D12: 24 | E12: 299 | F12: =D12*E12 -> 7176 | G12: 43688
A13: JUAN | B13: IMPRESORA | C13: NORTE | D13: 10 | E13: 99 | F13: =D13*E13 -> 990 | G13: 43481
A14: MARIA | B14: TV | C14: SUR | D14: 12 | E14: 399 | F14: =D14*E14 -> 4788 | G14: 43770
A15: EVA | B15: ORDENADOR | C15: NORTE | D15: 14 | E15: 299 | F15: =D15*E15 -> 4186 | G15: 43722
A16: PEDRO | B16: IMPRESORA | C16: SUR | D16: 16 | E16: 99 | F16: =D16*E16 -> 1584 | G16: 43578
... A38: MARIA | B38: TV | C38: SUR | D38: 12 | E38: 399 | F38: =D38*E38 -> 4788 | G38: 43592

Sheet Ejercicio 3B
A1: NOTA | B1: =+I4 -> 0
B2: Enunciado: | C2: Realiza los filtros indicados (cada filtro puntua 0,33)
A4: NOMBRE | B4: PRODUCTO | C4: ZONA DE VENTA | D4: UNIDADES | E4: PRECIO | F4: TOTAL | G4: FECHA DE LA VENTA | J4: Enunciado: | K4: Filtra las ventas de juan de tv o de maria de productos que contengan una o
A5: JUAN | B5: TV | C5: NORTE | D5: 10 | E5: 399 | F5: =D5*E5 -> 3990 | G5: 43664
A6: MARIA | B6: ORDENADOR | C6: SUR | D6: 12 | E6: 299 | F6: =D6*E6 -> 3588 | G6: 43528
A7: EVA | B7: IMPRESORA | C7: NORTE | D7: 14 | E7: 99 | F7: =D7*E7 -> 1386 | G7: 43668
A8: PEDRO | B8: TV | C8: SUR | D8: 16 | E8: 399 | F8: =D8*E8 -> 6384 | G8: 43706
A9: JUAN | B9: ORDENADOR | C9: NORTE | D9: 18 | E9: 299 | F9: =D9*E9 -> 5382 | G9: 43594
A10: MARIA | B10: IMPRESORA | C10: SUR | D10: 20 | E10: 99 | F10: =D10*E10 -> 1980 | G10: 43746
A11: EVA | B11: TV | C11: NORTE | D11: 22 | E11: 399 | F11: =D11*E11 -> 8778 | G11: 43693
A12: PEDRO | B12: ORDENADOR | C12: SUR | D12: 24 | E12: 299 | F12: =D12*E12 -> 7176 | G12: 43688
A13: JUAN | B13: IMPRESORA | C13: NORTE | D13: 10 | E13: 99 | F13: =D13*E13 -> 990 | G13: 43481
A14: MARIA | B14: TV | C14: SUR | D14: 12 | E14: 399 | F14: =D14*E14 -> 4788 | G14: 43770
A15: EVA | B15: ORDENADOR | C15: NORTE | D15: 14 | E15: 299 | F15: =D15*E15 -> 4186 | G15: 43722
A16: PEDRO | B16: IMPRESORA | C16: SUR | D16: 16 | E16: 99 | F16: =D16*E16 -> 1584 | G16: 43578
... A38: MARIA | B38: TV | C38: SUR | D38: 12 | E38: 399 | F38: =D38*E38 -> 4788 | G38: 43592

Sheet Ejercicio 3C
A1: NOTA | B1: =+I4 -> 0
B2: Enunciado: | C2: Realiza los filtros indicados (cada filtro puntua 0,33)
A4: NOMBRE | B4: PRODUCTO | C4: ZONA DE VENTA | D4: UNIDADES | E4: PRECIO | F4: TOTAL | G4: FECHA DE LA VENTA | J4: Enunciado: | K4: Filtra las ventas de juan de tv y de eva de ordenador, donde los totales esten entre 1000 y 3000 €
A5: JUAN | B5: TV | C5: NORTE | D5: 10 | E5: 399 | F5: =D5*E5 -> 3990 | G5: 43664
A6: MARIA | B6: ORDENADOR | C6: SUR | D6: 12 | E6: 299 | F6: =D6*E6 -> 3588 | G6: 43528
A7: EVA | B7: IMPRESORA | C7: NORTE | D7: 14 | E7: 99 | F7: =D7*E7 -> 1386 | G7: 43668
A8: PEDRO | B8: TV | C8: SUR | D8: 16 | E8: 399 | F8: =D8*E8 -> 6384 | G8: 43706
A9: JUAN | B9: ORDENADOR | C9: NORTE | D9: 18 | E9: 299 | F9: =D9*E9 -> 5382 | G9: 43594
A10: MARIA | B10: IMPRESORA | C10: SUR | D10: 20 | E10: 99 | F10: =D10*E10 -> 1980 | G10: 43746
A11: EVA | B11: TV | C11: NORTE | D11: 22 | E11: 399 | F11: =D11*E11 -> 8778 | G11: 43693
A12: PEDRO | B12: ORDENADOR | C12: SUR | D12: 24 | E12: 299 | F12: =D12*E12 -> 7176 | G12: 43688
A13: JUAN | B13: IMPRESORA | C13: NORTE | D13: 10 | E13: 99 | F13: =D13*E13 -> 990 | G13: 43481
A14: MARIA | B14: TV | C14: SUR | D14: 12 | E14: 399 | F14: =D14*E14 -> 4788 | G14: 43770
A15: EVA | B15: ORDENADOR | C15: NORTE | D15: 14 | E15: 299 | F15: =D15*E15 -> 4186 | G15: 43722
A16: PEDRO | B16: IMPRESORA | C16: SUR | D16: 16 | E16: 99 | F16: =D16*E16 -> 1584 | G16: 43578
... A38: MARIA | B38: TV | C38: SUR | D38: 12 | E38: 399 | F38: =D38*E38 -> 4788 | G38: 43592

Sheet Ejercicio 4
A1: NOTA | B1: =+F2 -> 0
E2: validación | G2: 2
H6: TIPOS DE LENGUAJES | J6: WEB | L6: OTROS
H7: WEB | J7: HTML | L7: JAVA
H8: OTROS | J8: CSS | L8: C
J9: JAVASCRIPT | L9: C#
J10: PHP | L10: COBOL
L11: Python
C12: TIPOS DE LENGUAJES | L12: R
C13: NOMBRE DEL LENGUAJE

Sheet Ejercicio 5
A1: NOTA | B1: =+N6 -> 0
M2: PRECIO UNIDAD | O2: 0.5
A3: Pais | B3: vendedor | C3: Producto | D3: Cantidad vendida | E3: PRECIO UNIDAD | F3: Ingresos | G3: Presupuesto | H3: Fecha | I3: Mes | M3: INGRESOS PAIS / MES | O3: 0.75
A4: francia | B4: David | C4: D | D4: 649 | F4: 32450 | G4: 27450 | H4: 43559 | I4: Abr | M4: UNIDADES VEND/PRODUCTO | O4: 0.75
A5: españa | B5: Victor | C5: A | D5: 292 | F5: 7008 | G5: 2008 | H5: 43563 | I5: Abr | M5: Análisis de datos | O5: 2.5
A6: españa | B6: Francisco | C6: B | D6: 1232 | F6: 34496 | G6: 29496 | H6: 43567 | I6: Abr | N6: =SUM(N2:N5) -> 0
A7: portugal | B7: David | C7: C | D7: 133 | F7: 4655 | G7: 500 | H7: 43571 | I7: Abr
A8: españa | B8: Victor | C8: D | D8: 483 | F8: 24150 | G8: 19150 | H8: 43575 | I8: Abr
A9: españa | B9: David | C9: B | D9: 334 | F9: 9352 | G9: 4352 | H9: 43558 | I9: Abr
A10: francia | B10: Francisco | C10: C | D10: 158 | F10: 5530 | G10: 530 | H10: 43578 | I10: Abr
A11: portugal | B11: Francisco | C11: B | D11: 96 | F11: 2688 | G11: 500 | H11: 43559 | I11: Abr | L11: Tenemos los siguientes datos. Se quiere analizar
A12: españa | B12: David | C12: C | D12: 367 | F12: 12845 | G12: 7845 | H12: 43563 | I12: Abr
A13: españa | B13: Victor | C13: D | D13: 348 | F13: 17400 | G13: 12400 | H13: 43567 | I13: Abr | L13: Se quiere saber como van los ingresos de productos por pais y mes.
A14: españa | B14: Francisco | C14: A | D14: 303 | F14: 7272 | G14: 2272 | H14: 43571 | I14: Abr | L14: Se quiere conocer el numero de ventas por vendedor y producto.
A15: portugal | B15: David | C15: B | D15: 415 | F15: 11620 | G15: 6620 | H15: 43575 | I15: Abr | L15: PRODUCTO | M15: PRECIO UNIDAD
A16: francia | B16: Victor | C16: C | D16: 46 | F16: 1610 | G16: 500 | H16: 43579 | I16: Abr | L16: A | M16: =+Tabla1[[#This Row],[Ingresos]]/Tabla1[[#This Row],[Cantidad vendida]] -> 35 | N16: 35
A17: francia | B17: Francisco | C17: D | D17: 85 | F17: 4250 | G17: 500 | H17: 43583 | I17: Abr | L17: B | M17: =+Tabla1[[#This Row],[Ingresos]]/Tabla1[[#This Row],[Cantidad vendida]] -> 50 | N17: 50
A18: francia | B18: Francisco | C18: D | D18: 473 | F18: 23650 | G18: 18650 | H18: 43576 | I18: Abr | L18: C | M18: =+Tabla1[[#This Row],[Ingresos]]/Tabla1[[#This Row],[Cantidad vendida]] -> 50 | N18: 50
A19: españa | B19: Victor | C19: B | D19: 334 | F19: 9352 | G19: 4352 | H19: 43558 | I19: Abr | L19: D | M19: =+Tabla1[[#This Row],[Ingresos]]/Tabla1[[#This Row],[Cantidad vendida]] -> 28 | N19: 28
A20: francia | B20: David | C20: C | D20: 158 | F20: 5530 | G20: 530 | H20: 43578 | I20: Abr
A21: francia | B21: Francisco | C21: C | D21: 724 | F21: 25340 | G21: 20340 | H21: 43494 | I21: Ene
A22: españa | B22: Francisco | C22: A | D22: 166 | F22: 3984 | G22: 500 | H22: 43494 | I22: Ene | L22: Analiza los resultados y comenta algún resultado que te permita tomar alguna decisión sobre los paises o los vendedores.
A23: españa | B23: David | C23: B | D23: 690 | F23: 19320 | G23: 14320 | H23: 43494 | I23: Ene
A24: españa | B24: Francisco | C24: D | D24: 837 | F24: 41850 | G24: 36850 | H24: 43494 | I24: Ene
A25: portugal | B25: David | C25: C | D25: 169 | F25: 5915 | G25: 915 | H25: 43494 | I25: Ene
A26: francia | B26: Francisco | C26: A | D26: 67 | F26: 1608 | G26: 500 | H26: 43494 | I26: Ene
A27: españa | B27: David | C27: B | D27: 131 | F27: 3668 | G27: 500 | H27: 43494 | I27: Ene
A28: españa | B28: Victor | C28: C | D28: 272 | F28: 9520 | G28: 4520 | H28: 43494 | I28: Ene
A29: portugal | B29: Francisco | C29: D | D29: 422 | F29: 21100 | G29: 16100 | H29: 43494 | I29: Ene
A30: españa | B30: David | C30: A | D30: 387 | F30: 9288 | G30: 4288 | H30: 43494 | I30: Ene
A31: francia | B31: Victor | C31: C | D31: 314 | F31: 10990 | G31: 5990 | H31: 43494 | I31: Ene
A32: españa | B32: David | C32: D | D32: 837 | F32: 41850 | G32: 36850 | H32: 43494 | I32: Ene
A33: francia | B33: David | C33: C | D33: 356 | F33: 12460 | G33: 7460 | H33: 43494 | I33: Ene
A34: portugal | B34: David | C34: A | D34: 586 | F34: 14064 | G34: 9064 | H34: 43499 | I34: Feb
... A98: francia | B98: Victor | C98: A | D98: 234 | F98: 5616 | G98: 616 | H98: 43588 | I98: May
